Workbook
Name TAX: '[1]Bid Tabulation'!$E$158
Name Type: '[2]Maintenance Work Order'!#REF!
Name valHighlight: #REF!

Sheet Dashboard
B1: Rekap Laporan Stok Barang
B2: Dashboard di bawah akan terisi otomatis ketika produk, pembelian, dan penjualan telah diisi
B4: Nilai Persediaan Total | D4: =SUM(Produk!H4:H7) -> 6220000
B5: 5 Barang Terjual Teratas Setiap Kuartal
B6: Kuartal 1 | C6: 1 | D6: =Penjualan!L4 -> Item 5
C7: 2 | D7: =Penjualan!L5 -> Item 8
C8: 3 | D8: =Penjualan!L6 -> Item 2
C9: 4 | D9: =Penjualan!L7 -> Item 6
C10: 5 | D10: =Penjualan!L8 -> Item 7
B11: Kuartal 2 | C11: 1 | D11: =Penjualan!O4 -> Item 7
C12: 2 | D12: =Penjualan!O5 -> Item 8
C13: 3 | D13: =Penjualan!O6 -> Item 5
C14: 4 | D14: =Penjualan!O7 -> Item 6
C15: 5 | D15: =Penjualan!O8 -> Item 10
B16: Kuartal 3 | C16: 1 | D16: =Penjualan!R4 -> Item 1
C17: 2 | D17: =Penjualan!R5 -> Item 2
C18: 3 | D18: =Penjualan!R6 -> Item 6
C19: 4 | D19: =Penjualan!R7 -> Item 5
C20: 5 | D20: =Penjualan!R8 -> Item 7
B21: Kuartal 4 | C21: 1 | D21: =Penjualan!U4 -> Item 8
C22: 2 | D22: =Penjualan!U5 -> Item 6
C23: 3 | D23: =Penjualan!U6 -> Item 2
C24: 4 | D24: =Penjualan!U7 -> Item 2
C25: 5 | D25: =Penjualan!U8 -> Item 10

Sheet Produk
B1: Rincian Produk
B2: Total Jumlah Persediaan yang Diterima per Kuartal | F2: Total Nilai Persediaan per Kuartal
B3: Data ini terisi otomatis dari tabel di bawah ini | F3: Data ini terisi otomatis dari tabel di bawah ini
B4: Kuartal 1 | D4: =SUM(Table44[Persediaan Masuk (Barang Datang)]) -> 42 | F4: Kuartal 1 | H4: =O21 -> 1555000
B5: Kuartal 2 | D5: =SUM(Table446[Persediaan Masuk (Barang Datang)]) -> 63 | F5: Kuartal 2 | H5: =O35 -> 1555000
B6: Kuartal 3 | D6: =SUM(Table4467[Persediaan Masuk (Barang Datang)]) -> 75 | F6: Kuartal 3 | H6: =O49 -> 1555000
B7: Kuartal 4 | D7: =SUM(Table4468[Persediaan Masuk (Barang Datang)]) -> 57 | F7: Kuartal 4 | H7: =O63 -> 1555000
B9: Kuartal 1
B10: Deskripsi Item | C10: Kode Barang | D10: Dimensi Barang | E10: Kategori | F10: Persediaan Awal | G10: Batas Minimum Persediaan (Reorder Level) | H10: Harga Pokok per Unit (HPP) | I10: Markup | J10: Harga Jual | K10: Total Pesanan | L10: Pesanan Tertunda (Belum Terkirim) | M10: Persediaan Masuk (Barang Datang) | N10: Persediaan Saat Ini | O10: Nilai Persediaan
B11: Item 1 | E11: Category A | F11: 0 | G11: 15 | H11: 2000 | I11: 1000 | J11: =H11+I11 -> 3000 | K11: 8 | L11: 1 | M11: 10 | N11: 5 | O11: =H11*N11 -> 10000
B12: Item 2 | E12: Category B | F12: 0 | G12: 14 | H12: 7500 | I12: 2500 | J12: =H12+I12 -> 10000 | K12: 10 | L12: 2 | M12: 10 | N12: 16 | O12: =H12*N12 -> 120000
B13: Item 3 | E13: Category C | F13: 0 | G13: 22 | H13: 10000 | I13: 3000 | J13: =H13+I13 -> 13000 | K13: 5 | L13: 1 | M13: 15 | N13: 25 | O13: =H13*N13 -> 250000
B14: Item 4 | E14: Category D | F14: 0 | G14: 35 | H14: 15000 | I14: 5000 | J14: =H14+I14 -> 20000 | K14: 12 | L14: 1 | M14: 5 | N14: 30 | O14: =H14*N14 -> 450000
B15: Item 5 | E15: Category E | F15: 0 | G15: 15 | H15: 29000 | I15: 13000 | J15: =H15+I15 -> 42000 | K15: 4 | L15: 3 | M15: 2 | N15: 25 | O15: =H15*N15 -> 725000
J16: =H16+I16 -> 0 | O16: =H16*N16 -> 0
J17: =H17+I17 -> 0 | O17: =H17*N17 -> 0
J18: =H18+I18 -> 0 | O18: =H18*N18 -> 0
J19: =H19+I19 -> 0 | O19: =H19*N19 -> 0
J20: =H20+I20 -> 0 | O20: =H20*N20 -> 0
B21: Total Nilai Persediaan | O21: =SUM(O11:O20) -> 1555000
B23: Kuartal 2
B24: Deskripsi Item | C24: Kode Barang | D24: Dimensi Barang | E24: Kategori | F24: Persediaan Awal | G24: Batas Minimum Persediaan (Reorder Level) | H24: Harga Pokok per Unit (HPP) | I24: Markup | J24: Harga Jual | K24: Total Pesanan | L24: Pesanan Tertunda (Belum Terkirim) | M24: Persediaan Masuk (Barang Datang) | N24: Persediaan Saat Ini | O24: Nilai Persediaan
B25: Item 1 | E25: Category A | F25: 0 | G25: 15 | H25: 2000 | I25: 1000 | J25: =H25+I25 -> 3000 | K25: 8 | L25: 1 | M25: 22 | N25: 5 | O25: =H25*N25 -> 10000
B26: Item 2 | E26: Category B | F26: 0 | G26: 14 | H26: 7500 | I26: 2500 | J26: =H26+I26 -> 10000 | K26: 10 | L26: 2 | M26: 32 | N26: 16 | O26: =H26*N26 -> 120000
B27: Item 3 | E27: Category C | F27: 0 | G27: 22 | H27: 10000 | I27: 3000 | J27: =H27+I27 -> 13000 | K27: 5 | L27: 1 | M27: 6 | N27: 25 | O27: =H27*N27 -> 250000
B28: Item 4 | E28: Category D | F28: 0 | G28: 35 | H28: 15000 | I28: 5000 | J28: =H28+I28 -> 20000 | K28: 12 | L28: 1 | M28: 3 | N28: 30 | O28: =H28*N28 -> 450000
B29: Item 5 | E29: Category E | F29: 0 | G29: 15 | H29: 29000 | I29: 13000 | J29: =H29+I29 -> 42000 | K29: 4 | L29: 3 | M29: 0 | N29: 25 | O29: =H29*N29 -> 725000
J30: =H30+I30 -> 0 | O30: =H30*N30 -> 0
J31: =H31+I31 -> 0 | O31: =H31*N31 -> 0
J32: =H32+I32 -> 0 | O32: =H32*N32 -> 0
J33: =H33+I33 -> 0 | O33: =H33*N33 -> 0
J34: =H34+I34 -> 0 | O34: =H34*N34 -> 0
B35: Total Nilai Persediaan | O35: =SUM(O25:O34) -> 1555000
B37: Kuartal 3
B38: Deskripsi Item | C38: Kode Barang | D38: Dimensi Barang | E38: Kategori | F38: Persediaan Awal | G38: Batas Minimum Persediaan (Reorder Level) | H38: Harga Pokok per Unit (HPP) | I38: Markup | J38: Harga Jual | K38: Total Pesanan | L38: Pesanan Tertunda (Belum Terkirim) | M38: Persediaan Masuk (Barang Datang) | N38: Persediaan Saat Ini | O38: Nilai Persediaan
B39: Item 1 | E39: Category A | F39: 0 | G39: 15 | H39: 2000 | I39: 1000 | J39: =H39+I39 -> 3000 | K39: 8 | L39: 1 | M39: 40 | N39: 5 | O39: =H39*N39 -> 10000
B40: Item 2 | E40: Category B | F40: 0 | G40: 14 | H40: 7500 | I40: 2500 | J40: =H40+I40 -> 10000 | K40: 10 | L40: 2 | M40: 4 | N40: 16 | O40: =H40*N40 -> 120000
B41: Item 3 | E41: Category C | F41: 0 | G41: 22 | H41: 10000 | I41: 3000 | J41: =H41+I41 -> 13000 | K41: 5 | L41: 1 | M41: 6 | N41: 25 | O41: =H41*N41 -> 250000
B42: Item 4 | E42: Category D | F42: 0 | G42: 35 | H42: 15000 | I42: 5000 | J42: =H42+I42 -> 20000 | K42: 12 | L42: 1 | M42: 7 | N42: 30 | O42: =H42*N42 -> 450000
B43: Item 5 | E43: Category E | F43: 0 | G43: 15 | H43: 29000 | I43: 13000 | J43: =H43+I43 -> 42000 | K43: 4 | L43: 3 | M43: 18 | N43: 25 | O43: =H43*N43 -> 725000
...

Sheet Pembelian
B1: Rincian Pembelian
B2: Total Pengeluaran untuk Persediaan
B3: Data ini terisi otomatis dari tabel di bawah ini
B4: Kuartal 1 | D4: =SUM(I11:I20) -> 1137000
B5: Kuartal 2 | D5: =SUM(I24:I33) -> 825000
B6: Kuartal 3 | D6: =SUM(I37:I46) -> 1284000
B7: Kuartal 4 | D7: =SUM(I50:I59) -> 1331000
B9: Kuartal 1
B10: Nomor Pesanan | C10: Deskripsi Item | D10: Tanggal Pemesanan | E10: Tanggal Perkiraan Barang Datang | F10: Vendor/Pemasok/Supplier | G10: Jumlah Unit Dipesan | H10: Harga per Unit | I10: Total Pembelian
B11: 1245 | C11: Item 1 | D11: DD/MM/YY | E11: DD/MM/YY | F11: Nama | G11: 10 | H11: 15000 | I11: =G11*H11 -> 150000
C12: Item 2 | D12: DD/MM/YY | E12: DD/MM/YY | G12: 12 | H12: 14000 | I12: =G12*H12 -> 168000
C13: Item 3 | D13: DD/MM/YY | E13: DD/MM/YY | G13: 8 | H13: 6000 | I13: =G13*H13 -> 48000
C14: Item 4 | D14: DD/MM/YY | E14: DD/MM/YY | G14: 5 | H14: 6000 | I14: =G14*H14 -> 30000
C15: Item 5 | D15: DD/MM/YY | E15: DD/MM/YY | G15: 24 | H15: 11000 | I15: =G15*H15 -> 264000
C16: Item 6 | D16: DD/MM/YY | E16: DD/MM/YY | G16: 15 | H16: 6000 | I16: =G16*H16 -> 90000
C17: Item 7 | D17: DD/MM/YY | E17: DD/MM/YY | G17: 12 | H17: 6000 | I17: =G17*H17 -> 72000
C18: Item 8 | D18: DD/MM/YY | E18: DD/MM/YY | G18: 22 | H18: 12000 | I18: =G18*H18 -> 264000
C19: Item 9 | D19: DD/MM/YY | E19: DD/MM/YY | G19: 6 | H19: 4000 | I19: =G19*H19 -> 24000
C20: Item 10 | D20: DD/MM/YY | E20: DD/MM/YY | G20: 9 | H20: 3000 | I20: =G20*H20 -> 27000
B22: Kuartal 2
B23: Nomor Pesanan | C23: Deskripsi Item | D23: Tanggal Pemesanan | E23: Tanggal Perkiraan Barang Datang | F23: Vendor/Pemasok/Supplier | G23: Jumlah Unit Dipesan | H23: Harga per Unit | I23: Total Pembelian
B24: 1245 | C24: Item 1 | D24: DD/MM/YY | E24: DD/MM/YY | F24: Nama | G24: 5 | H24: 15000 | I24: =G24*H24 -> 75000
C25: Item 2 | D25: DD/MM/YY | E25: DD/MM/YY | G25: 6 | H25: 14000 | I25: =G25*H25 -> 84000
C26: Item 3 | D26: DD/MM/YY | E26: DD/MM/YY | G26: 15 | H26: 6000 | I26: =G26*H26 -> 90000
C27: Item 4 | D27: DD/MM/YY | E27: DD/MM/YY | G27: 15 | H27: 6000 | I27: =G27*H27 -> 90000
C28: Item 5 | D28: DD/MM/YY | E28: DD/MM/YY | G28: 15 | H28: 11000 | I28: =G28*H28 -> 165000
C29: Item 6 | D29: DD/MM/YY | E29: DD/MM/YY | G29: 4 | H29: 6000 | I29: =G29*H29 -> 24000
C30: Item 7 | D30: DD/MM/YY | E30: DD/MM/YY | G30: 6 | H30: 6000 | I30: =G30*H30 -> 36000
C31: Item 8 | D31: DD/MM/YY | E31: DD/MM/YY | G31: 18 | H31: 12000 | I31: =G31*H31 -> 216000
C32: Item 9 | D32: DD/MM/YY | E32: DD/MM/YY | G32: 6 | H32: 4000 | I32: =G32*H32 -> 24000
C33: Item 10 | D33: DD/MM/YY | E33: DD/MM/YY | G33: 7 | H33: 3000 | I33: =G33*H33 -> 21000
B35: Kuartal 3
B36: Nomor Pesanan | C36: Deskripsi Item | D36: Tanggal Pemesanan | E36: Tanggal Perkiraan Barang Datang | F36: Vendor/Pemasok/Supplier | G36: Jumlah Unit Dipesan | H36: Harga per Unit | I36: Total Pembelian
B37: 1245 | C37: Item 1 | D37: DD/MM/YY | E37: DD/MM/YY | F37: Nama | G37: 1 | H37: 15000 | I37: =G37*H37 -> 15000
C38: Item 2 | D38: DD/MM/YY | E38: DD/MM/YY | G38: 30 | H38: 14000 | I38: =G38*H38 -> 420000
C39: Item 3 | D39: DD/MM/YY | E39: DD/MM/YY | G39: 8 | H39: 6000 | I39: =G39*H39 -> 48000
C40: Item 4 | D40: DD/MM/YY | E40: DD/MM/YY | G40: 5 | H40: 6000 | I40: =G40*H40 -> 30000
C41: Item 5 | D41: DD/MM/YY | E41: DD/MM/YY | G41: 12 | H41: 11000 | I41: =G41*H41 -> 132000
C42: Item 6 | D42: DD/MM/YY | E42: DD/MM/YY | G42: 25 | H42: 6000 | I42: =G42*H42 -> 150000
C43: Item 7 | D43: DD/MM/YY | E43: DD/MM/YY | G43: 6 | H43: 6000 | I43: =G43*H43 -> 36000
...

Sheet Penjualan
B1: Rincian Penjualan
B2: Total Pendapatan Penjualan per Kuartal | F2: Total Unit Terjual per Kuartal | K2: 5 Barang Terlaris
B3: Data ini terisi otomatis dari tabel di bawah ini | F3: Data ini terisi otomatis dari tabel di bawah ini | K3: Data ini terisi otomatis dari tabel di bawah ini
B4: Kuartal 1 | D4: =SUM(I12:I21) -> 5069000 | F4: Kuartal 1 | H4: =SUM(G12:G21) -> 128 | K4: Q1 | L4: {=INDEX($C$12:$C$21, MATCH(LARGE($G$12:$G$21, ROW(1:1)), $G$12:$G$21, 0))} -> Item 5 | N4: Q2 | O4: {=INDEX($C$25:$C$34, MATCH(LARGE($G$25:$G$34, ROW(1:1)), $G$25:$G$34, 0))} -> Item 7 | Q4: Q3 | R4: {=INDEX($C$38:$C$47, MATCH(LARGE($G$38:$G$47, ROW(1:1)), $G$38:$G$47, 0))} -> Item 1 | T4: Q4 | U4: {=INDEX($C$51:$C$60, MATCH(LARGE($G$51:$G$60, ROW(1:1)), $G$51:$G$60, 0))} -> Item 8
B5: Kuartal 2 | D5: =SUM(I25:I34) -> 3610000 | F5: Kuartal 2 | H5: =SUM(G25:G34) -> 117 | L5: {=INDEX($C$12:$C$21, MATCH(LARGE($G$12:$G$21, ROW(2:2)), $G$12:$G$21, 0))} -> Item 8 | O5: {=INDEX($C$25:$C$34, MATCH(LARGE($G$25:$G$34, ROW(2:2)), $G$25:$G$34, 0))} -> Item 8 | R5: {=INDEX($C$38:$C$47, MATCH(LARGE($G$38:$G$47, ROW(2:2)), $G$38:$G$47, 0))} -> Item 2 | U5: {=INDEX($C$51:$C$60, MATCH(LARGE($G$51:$G$60, ROW(2:2)), $G$51:$G$60, 0))} -> Item 6
B6: Kuartal 3 | D6: =SUM(I38:I47) -> 5844000 | F6: Kuartal 3 | H6: =SUM(G38:G47) -> 153 | L6: {=INDEX($C$12:$C$21, MATCH(LARGE($G$12:$G$21, ROW(3:3)), $G$12:$G$21, 0))} -> Item 2 | O6: {=INDEX($C$25:$C$34, MATCH(LARGE($G$25:$G$34, ROW(3:3)), $G$25:$G$34, 0))} -> Item 5 | R6: {=INDEX($C$38:$C$47, MATCH(LARGE($G$38:$G$47, ROW(3:3)), $G$38:$G$47, 0))} -> Item 6 | U6: {=INDEX($C$51:$C$60, MATCH(LARGE($G$51:$G$60, ROW(3:3)), $G$51:$G$60, 0))} -> Item 2
B7: Kuartal 4 | D7: =SUM(I51:I60) -> 3294000 | F7: Kuartal 4 | H7: =SUM(G51:G60) -> 98 | L7: {=INDEX($C$12:$C$21, MATCH(LARGE($G$12:$G$21, ROW(4:4)), $G$12:$G$21, 0))} -> Item 6 | O7: {=INDEX($C$25:$C$34, MATCH(LARGE($G$25:$G$34, ROW(4:4)), $G$25:$G$34, 0))} -> Item 6 | R7: {=INDEX($C$38:$C$47, MATCH(LARGE($G$38:$G$47, ROW(4:4)), $G$38:$G$47, 0))} -> Item 5 | U7: {=INDEX($C$51:$C$60, MATCH(LARGE($G$51:$G$60, ROW(4:4)), $G$51:$G$60, 0))} -> Item 2
L8: {=INDEX($C$12:$C$21, MATCH(LARGE($G$12:$G$21, ROW(5:5)), $G$12:$G$21, 0))} -> Item 7 | O8: {=INDEX($C$25:$C$34, MATCH(LARGE($G$25:$G$34, ROW(5:5)), $G$25:$G$34, 0))} -> Item 10 | R8: {=INDEX($C$38:$C$47, MATCH(LARGE($G$38:$G$47, ROW(5:5)), $G$38:$G$47, 0))} -> Item 7 | U8: {=INDEX($C$51:$C$60, MATCH(LARGE($G$51:$G$60, ROW(5:5)), $G$51:$G$60, 0))} -> Item 10
B10: Kuartal 1
B11: Nomor Invoice | C11: Barang Terjual | D11: Tanggal Transaksi | E11: Tanggal Pengiriman | F11: Nama Customer | G11: Jumlah Unit Terjual | H11: Harga Jual per Unit | I11: Total Penjualan
B12: 1245 | C12: Item 1 | D12: DD/MM/YY | E12: DD/MM/YY | F12: Customer A | G12: 10 | H12: 50000 | I12: =G12*H12 -> 500000
C13: Item 2 | D13: DD/MM/YY | E13: DD/MM/YY | F13: Customer B | G13: 17 | H13: 65000 | I13: =G13*H13 -> 1105000
C14: Item 3 | D14: DD/MM/YY | E14: DD/MM/YY | F14: Customer C | G14: 8 | H14: 25000 | I14: =G14*H14 -> 200000
C15: Item 4 | D15: DD/MM/YY | E15: DD/MM/YY | F15: Customer D | G15: 5 | H15: 25000 | I15: =G15*H15 -> 125000
C16: Item 5 | D16: DD/MM/YY | E16: DD/MM/YY | F16: Customer E | G16: 24 | H16: 60000 | I16: =G16*H16 -> 1440000
C17: Item 6 | D17: DD/MM/YY | E17: DD/MM/YY | F17: Customer F | G17: 15 | H17: 15000 | I17: =G17*H17 -> 225000
C18: Item 7 | D18: DD/MM/YY | E18: DD/MM/YY | F18: Customer G | G18: 12 | H18: 12000 | I18: =G18*H18 -> 144000
C19: Item 8 | D19: DD/MM/YY | E19: DD/MM/YY | F19: Customer H | G19: 22 | H19: 55000 | I19: =G19*H19 -> 1210000
C20: Item 9 | D20: DD/MM/YY | E20: DD/MM/YY | F20: Customer I | G20: 6 | H20: 8000 | I20: =G20*H20 -> 48000
C21: Item 10 | D21: DD/MM/YY | E21: DD/MM/YY | F21: Customer J | G21: 9 | H21: 8000 | I21: =G21*H21 -> 72000
B23: Kuartal 2
B24: Nomor Invoice | C24: Barang Terjual | D24: Tanggal Transaksi | E24: Tanggal Pengiriman | F24: Nama Customer | G24: Jumlah Unit Terjual | H24: Harga Jual per Unit | I24: Total Penjualan
B25: 1245 | C25: Item 1 | D25: DD/MM/YY | E25: DD/MM/YY | F25: Customer A | G25: 7 | H25: 50000 | I25: =G25*H25 -> 350000
C26: Item 2 | D26: DD/MM/YY | E26: DD/MM/YY | F26: Customer B | G26: 6 | H26: 65000 | I26: =G26*H26 -> 390000
C27: Item 3 | D27: DD/MM/YY | E27: DD/MM/YY | F27: Customer C | G27: 7 | H27: 25000 | I27: =G27*H27 -> 175000
C28: Item 4 | D28: DD/MM/YY | E28: DD/MM/YY | F28: Customer D | G28: 3 | H28: 25000 | I28: =G28*H28 -> 75000
C29: Item 5 | D29: DD/MM/YY | E29: DD/MM/YY | F29: Customer E | G29: 12 | H29: 60000 | I29: =G29*H29 -> 720000
C30: Item 6 | D30: DD/MM/YY | E30: DD/MM/YY | F30: Customer F | G30: 10 | H30: 15000 | I30: =G30*H30 -> 150000
C31: Item 7 | D31: DD/MM/YY | E31: DD/MM/YY | F31: Customer G | G31: 35 | H31: 12000 | I31: =G31*H31 -> 420000
C32: Item 8 | D32: DD/MM/YY | E32: DD/MM/YY | F32: Customer H | G32: 22 | H32: 55000 | I32: =G32*H32 -> 1210000
C33: Item 9 | D33: DD/MM/YY | E33: DD/MM/YY | F33: Customer I | G33: 6 | H33: 8000 | I33: =G33*H33 -> 48000
C34: Item 10 | D34: DD/MM/YY | E34: DD/MM/YY | F34: Customer J | G34: 9 | H34: 8000 | I34: =G34*H34 -> 72000
B36: Kuartal 3
B37: Nomor Invoice | C37: Barang Terjual | D37: Tanggal Transaksi | E37: Tanggal Pengiriman | F37: Nama Customer | G37: Jumlah Unit Terjual | H37: Harga Jual per Unit | I37: Total Penjualan
B38: 1245 | C38: Item 1 | D38: DD/MM/YY | E38: DD/MM/YY | F38: Customer A | G38: 45 | H38: 50000 | I38: =G38*H38 -> 2250000
C39: Item 2 | D39: DD/MM/YY | E39: DD/MM/YY | F39: Customer B | G39: 18 | H39: 65000 | I39: =G39*H39 -> 1170000
C40: Item 3 | D40: DD/MM/YY | E40: DD/MM/YY | F40: Customer C | G40: 9 | H40: 25000 | I40: =G40*H40 -> 225000
C41: Item 4 | D41: DD/MM/YY | E41: DD/MM/YY | F41: Customer D | G41: 6 | H41: 25000 | I41: =G41*H41 -> 150000
C42: Item 5 | D42: DD/MM/YY | E42: DD/MM/YY | F42: Customer E | G42: 14 | H42: 60000 | I42: =G42*H42 -> 840000
C43: Item 6 | D43: DD/MM/YY | E43: DD/MM/YY | F43: Customer F | G43: 15 | H43: 15000 | I43: =G43*H43 -> 225000
...
